30/08/2019 11:19:15 AM Python Script is: morePVs.py
30/08/2019 11:19:15 AM study_name = test_capex2
30/08/2019 11:19:15 AM Running Scenario number 1 
30/08/2019 11:19:15 AM **************CHECKSUM ERROR************************
30/08/2019 11:19:15 AM Study: test_capex2  Scenario: 1 
30/08/2019 11:19:15 AM Tot Building Cost 27081.094010 Checksum -27081.094010
30/08/2019 11:19:15 AM 


 Exception !!!!!!
Traceback (most recent call last):
  File "/Users/mikeroberts/Documents/python/morePVs/morePVs.py", line 2654, in main
    runScenario(s)
  File "/Users/mikeroberts/Documents/python/morePVs/morePVs.py", line 2629, in runScenario
    scenario.logScenarioData()
  File "/Users/mikeroberts/Documents/python/morePVs/morePVs.py", line 2299, in logScenarioData
    study.op.loc[self.name, 'pv_capex_repayment'] = self.pv_capex_repayment
  File "/Users/mikeroberts/anaconda3/lib/python3.7/site-packages/pandas/core/indexing.py", line 190, in __setitem__
    self._setitem_with_indexer(indexer, value)
  File "/Users/mikeroberts/anaconda3/lib/python3.7/site-packages/pandas/core/indexing.py", line 366, in _setitem_with_indexer
    self._setitem_with_indexer(new_indexer, value)
  File "/Users/mikeroberts/anaconda3/lib/python3.7/site-packages/pandas/core/indexing.py", line 611, in _setitem_with_indexer
    raise ValueError('Must have equal len keys and value '
ValueError: Must have equal len keys and value when setting with an iterable
