30/08/2019 11:45:30 AM Python Script is: morePVs.py
30/08/2019 11:45:30 AM study_name = test_capex2
30/08/2019 11:45:30 AM Running Scenario number 1 
30/08/2019 11:45:30 AM **************CHECKSUM ERROR************************
30/08/2019 11:45:30 AM Study: test_capex2  Scenario: 1 
30/08/2019 11:45:30 AM Tot Building Cost 63189.219358 Checksum -63189.219358
30/08/2019 11:45:30 AM Completed Scenario 1
30/08/2019 11:45:30 AM Running Scenario number 2 
30/08/2019 11:45:30 AM **************CHECKSUM ERROR************************
30/08/2019 11:45:30 AM Study: test_capex2  Scenario: 2 
30/08/2019 11:45:30 AM Tot Building Cost 75300.894344 Checksum -63189.219358
30/08/2019 11:45:30 AM Completed Scenario 2
30/08/2019 11:45:30 AM Running Scenario number 0 
30/08/2019 11:45:31 AM 


 Exception !!!!!!
Traceback (most recent call last):
  File "/Users/mikeroberts/Documents/python/morePVs/morePVs.py", line 2659, in main
    runScenario(s)
  File "/Users/mikeroberts/Documents/python/morePVs/morePVs.py", line 2634, in runScenario
    scenario.logScenarioData()
  File "/Users/mikeroberts/Documents/python/morePVs/morePVs.py", line 2304, in logScenarioData
    study.op.loc[self.name, 'pv_capex_repayment'] = self.pv_capex_repayment['total_system']
KeyError: 'total_system'
