30/08/2019 10:55:21 AM Python Script is: morePVs.py
30/08/2019 10:55:21 AM study_name = test_capex1
30/08/2019 10:55:22 AM Running Scenario number 1 
30/08/2019 10:55:23 AM 


 Exception !!!!!!
Traceback (most recent call last):
  File "pandas/_libs/tslib.pyx", line 586, in pandas._libs.tslib.array_to_datetime
  File "pandas/_libs/tslibs/np_datetime.pyx", line 184, in pandas._libs.tslibs.np_datetime._string_to_dts
ValueError: Month out of range in datetime string "15/10/2017 2:00"

During handling of the above exception, another exception occurred:

Traceback (most recent call last):
  File "/Users/mikeroberts/Documents/python/morePVs/morePVs.py", line 2654, in main
    runScenario(s)
  File "/Users/mikeroberts/Documents/python/morePVs/morePVs.py", line 2574, in runScenario
    scenario = Scenario(scenario_name=scenario_name)
  File "/Users/mikeroberts/Documents/python/morePVs/morePVs.py", line 1859, in __init__
    self.pv = pd.read_csv(self.pvFile, parse_dates=['timestamp'], dayfirst=True)
  File "/Users/mikeroberts/anaconda3/lib/python3.7/site-packages/pandas/io/parsers.py", line 702, in parser_f
    return _read(filepath_or_buffer, kwds)
  File "/Users/mikeroberts/anaconda3/lib/python3.7/site-packages/pandas/io/parsers.py", line 435, in _read
    data = parser.read(nrows)
  File "/Users/mikeroberts/anaconda3/lib/python3.7/site-packages/pandas/io/parsers.py", line 1139, in read
    ret = self._engine.read(nrows)
  File "/Users/mikeroberts/anaconda3/lib/python3.7/site-packages/pandas/io/parsers.py", line 2068, in read
    names, data = self._do_date_conversions(names, data)
  File "/Users/mikeroberts/anaconda3/lib/python3.7/site-packages/pandas/io/parsers.py", line 1820, in _do_date_conversions
    self.index_names, names, keep_date_col=self.keep_date_col)
  File "/Users/mikeroberts/anaconda3/lib/python3.7/site-packages/pandas/io/parsers.py", line 3223, in _process_date_conversion
    data_dict[colspec] = converter(data_dict[colspec])
  File "/Users/mikeroberts/anaconda3/lib/python3.7/site-packages/pandas/io/parsers.py", line 3170, in converter
    infer_datetime_format=infer_datetime_format
  File "/Users/mikeroberts/anaconda3/lib/python3.7/site-packages/pandas/core/tools/datetimes.py", line 609, in to_datetime
    result = convert_listlike(arg, box, format)
  File "/Users/mikeroberts/anaconda3/lib/python3.7/site-packages/pandas/core/tools/datetimes.py", line 302, in _convert_listlike_datetimes
    allow_object=True)
  File "/Users/mikeroberts/anaconda3/lib/python3.7/site-packages/pandas/core/arrays/datetimes.py", line 1857, in objects_to_datetime64ns
    require_iso8601=require_iso8601
  File "pandas/_libs/tslib.pyx", line 460, in pandas._libs.tslib.array_to_datetime
  File "pandas/_libs/tslib.pyx", line 605, in pandas._libs.tslib.array_to_datetime
  File "pandas/_libs/tslibs/parsing.pyx", line 91, in pandas._libs.tslibs.parsing.parse_datetime_string
  File "pandas/_libs/tslibs/parsing.pyx", line 305, in pandas._libs.tslibs.parsing._parse_dateabbr_string
  File "/Users/mikeroberts/anaconda3/lib/python3.7/_strptime.py", line 574, in _strptime_datetime
    def _strptime_datetime(cls, data_string, format="%a %b %d %H:%M:%S %Y"):
KeyboardInterrupt
